Workbook
Name CoffeeNameAverage: INDEX(#REF!, MATCH(#REF!,#REF!, 0))
Name CoffeeNameIncome: INDEX(#REF!, MATCH(#REF!,#REF!, 0))
Name CoffeeNameQuantity: INDEX(#REF!, MATCH(#REF!,#REF!, 0))
Name CoffeeNameTotal: INDEX(#REF!, MATCH(#REF!,#REF!, 0))
Name HourOfDayAverage: INDEX(#REF!, MATCH(#REF!,#REF!, 0))
Name HourOfDayIncome: INDEX(#REF!, MATCH(#REF!,#REF!, 0))
Name HourofDayQuantity: INDEX(#REF!, MATCH(#REF!,#REF!, 0))
Name HourOfDayTotal: INDEX(#REF!, MATCH(#REF!,#REF!, 0))
Name MonthAverage: INDEX(#REF!, MATCH(#REF!,#REF!, 0))
Name MonthIncome: INDEX(#REF!, MATCH(#REF!,#REF!, 0))
Name MonthQuantity: INDEX(#REF!, MATCH(#REF!,#REF!, 0))
Name MonthTotal: INDEX(#REF!, MATCH(#REF!,#REF!, 0))
Name Slicer_coffee_name: #N/A
Name Slicer_hour_of_day: #N/A
Name Slicer_Month_name: #N/A
Name Slicer_Time_of_Day: #N/A
Name Slicer_Weekday: #N/A
Name TimeOfDayAverage: INDEX(#REF!, MATCH(#REF!,#REF!, 0))
Name TimeOfDayIncome: INDEX(#REF!, MATCH(#REF!,#REF!, 0))
Name TimeofDayQuantity: INDEX(#REF!, MATCH(#REF!,#REF!, 0))
Name TimeOfDayTotal: INDEX(#REF!, MATCH(#REF!,#REF!, 0))
Name WeekdayAverage: INDEX(#REF!, MATCH(#REF!,#REF!, 0))
Name WeekdayIncome: INDEX(#REF!, MATCH(#REF!,#REF!, 0))
Name WeekdayQuantity: INDEX(#REF!, MATCH(#REF!,#REF!, 0))
Name WeekdayTotal: INDEX(#REF!, MATCH(#REF!,#REF!, 0))

Sheet Dashboard
A1: Coffee Product & Payment Insights Dashboard
B2: Total Revenue | F2: Transactions | J2: Avg/Order | N2: Best Coffee
B3: =GETPIVOTDATA("money",KPI!$A$3) -> 112245.58 | F3: =GETPIVOTDATA("Count of Index",KPI!$A$3) -> 3547 | J3: =B3/F3 -> 31.645216 | M3: =KPI!A4 -> Latte
M5: Orders
N6: 6 | O6: 7 | P6: 8 | Q6: 9 | R6: 10 | S6: 11 | T6: 12 | U6: 13 | V6: 14 | W6: 15 | X6: 16 | Y6: 17 | Z6: 18 | AA6: 19 | AB6: 20 | AC6: 21 | AD6: 22
M7: Monday | N7: 2 | O7: 21 | P7: 42 | Q7: 38 | R7: 52 | S7: 38 | T7: 24 | U7: 28 | V7: 42 | W7: 37 | X7: 46 | Y7: 36 | Z7: 34 | AA7: 43 | AB7: 22 | AC7: 26 | AD7: 13
M8: Tuesday | O8: 15 | P8: 49 | Q8: 39 | R8: 48 | S8: 56 | T8: 30 | U8: 22 | V8: 31 | W8: 27 | X8: 50 | Y8: 36 | Z8: 34 | AA8: 52 | AB8: 37 | AC8: 33 | AD8: 13
M9: Wednesday | O9: 17 | P9: 29 | Q9: 25 | R9: 47 | S9: 47 | T9: 34 | U9: 44 | V9: 15 | W9: 30 | X9: 42 | Y9: 35 | Z9: 35 | AA9: 35 | AB9: 25 | AC9: 30 | AD9: 10
M10: Thursday | O10: 13 | P10: 22 | Q10: 34 | R10: 49 | S10: 28 | T10: 30 | U10: 31 | V10: 33 | W10: 35 | X10: 40 | Y10: 36 | Z10: 30 | AA10: 43 | AB10: 30 | AC10: 43 | AD10: 13
M11: Friday | N11: 3 | O11: 18 | P11: 49 | Q11: 51 | R11: 43 | S11: 29 | T11: 37 | U11: 35 | V11: 33 | W11: 34 | X11: 33 | Y11: 42 | Z11: 31 | AA11: 26 | AB11: 16 | AC11: 17 | AD11: 35
M12: Saturday | O12: 2 | P12: 24 | Q12: 34 | R12: 42 | S12: 55 | T12: 46 | U12: 32 | V12: 37 | W12: 37 | X12: 42 | Y12: 28 | Z12: 18 | AA12: 19 | AB12: 21 | AC12: 12 | AD12: 21
M13: Sunday | O13: 2 | P13: 20 | Q13: 21 | R13: 47 | S13: 30 | T13: 40 | U13: 33 | V13: 34 | W13: 36 | X13: 25 | Y13: 24 | Z13: 36 | AA13: 11 | AB13: 18 | AC13: 34 | AD13: 8

Sheet Top Coffee Types
A3: Row Labels | B3: Quantity sold | C3: Sum of money
A4: Espresso | B4: 129 | C4: 2690.28
A5: Cortado | B5: 287 | C5: 7384.86
A6: Cocoa | B6: 239 | C6: 8521.16
A7: Hot Chocolate | B7: 276 | C7: 9933.46
A8: Americano | B8: 564 | C8: 14650.26
A9: Cappuccino | B9: 486 | C9: 17439.14
A10: Americano with Milk | B10: 809 | C10: 24751.12
A11: Latte | B11: 757 | C11: 26875.3
A12: Grand Total | B12: 3547 | C12: 112245.58

Sheet KPI
A3: Row Labels | B3: Sum of money | C3: Count of Index
A4: Latte | B4: 26875.3 | C4: 757
A5: Americano with Milk | B5: 24751.12 | C5: 809
A6: Cappuccino | B6: 17439.14 | C6: 486
A7: Americano | B7: 14650.26 | C7: 564
A8: Hot Chocolate | B8: 9933.46 | C8: 276
A9: Cocoa | B9: 8521.16 | C9: 239
A10: Cortado | B10: 7384.86 | C10: 287
A11: Espresso | B11: 2690.28 | C11: 129
A12: Grand Total | B12: 112245.58 | C12: 3547

Sheet Forecast Sheet
A1: Date | B1: Sum of money | C1: Forecast(Sum of money) | D1: Lower Confidence Bound(Sum of money) | E1: Upper Confidence Bound(Sum of money)
A2: 45352 | B2: 396.3
A3: 45353 | B3: 188.1
A4: 45354 | B4: 309.1
A5: 45355 | B5: 135.2
A6: 45356 | B6: 338.5
A7: 45357 | B7: 135.2
A8: 45358 | B8: 140.1
A9: 45359 | B9: 265.5
A10: 45360 | B10: 439.4
A11: 45361 | B11: 91.6
A12: 45362 | B12: 135.2
A13: 45363 | B13: 188.1
... A388: 45738 | B388: 365.42
A389: 45739 | B389: 204.76 | C389: 204.76 | D389: 204.76 | E389: 204.76
A390: 45740 | C390: =_xlfn.FORECAST.ETS(A390,$B$2:$B$389,$A$2:$A$389,1,1) -> 195.6996 | D390: =C390-_xlfn.FORECAST.ETS.CONFINT(A390,$B$2:$B$389,$A$2:$A$389,0.95,1,1) -> -98.68907 | E390: =C390+_xlfn.FORECAST.ETS.CONFINT(A390,$B$2:$B$389,$A$2:$A$389,0.95,1,1) -> 490.08827
A391: 45741 | C391: =_xlfn.FORECAST.ETS(A391,$B$2:$B$389,$A$2:$A$389,1,1) -> 186.31289 | D391: =C391-_xlfn.FORECAST.ETS.CONFINT(A391,$B$2:$B$389,$A$2:$A$389,0.95,1,1) -> -117.27934 | E391: =C391+_xlfn.FORECAST.ETS.CONFINT(A391,$B$2:$B$389,$A$2:$A$389,0.95,1,1) -> 489.90512
A392: 45742 | C392: =_xlfn.FORECAST.ETS(A392,$B$2:$B$389,$A$2:$A$389,1,1) -> 138.21588 | D392: =C392-_xlfn.FORECAST.ETS.CONFINT(A392,$B$2:$B$389,$A$2:$A$389,0.95,1,1) -> -174.379 | E392: =C392+_xlfn.FORECAST.ETS.CONFINT(A392,$B$2:$B$389,$A$2:$A$389,0.95,1,1) -> 450.81077
A393: 45743 | C393: =_xlfn.FORECAST.ETS(A393,$B$2:$B$389,$A$2:$A$389,1,1) -> 169.58322 | D393: =C393-_xlfn.FORECAST.ETS.CONFINT(A393,$B$2:$B$389,$A$2:$A$389,0.95,1,1) -> -151.83057 | E393: =C393+_xlfn.FORECAST.ETS.CONFINT(A393,$B$2:$B$389,$A$2:$A$389,0.95,1,1) -> 490.997
A394: 45744 | C394: =_xlfn.FORECAST.ETS(A394,$B$2:$B$389,$A$2:$A$389,1,1) -> 137.15958 | D394: =C394-_xlfn.FORECAST.ETS.CONFINT(A394,$B$2:$B$389,$A$2:$A$389,0.95,1,1) -> -192.90434 | E394: =C394+_xlfn.FORECAST.ETS.CONFINT(A394,$B$2:$B$389,$A$2:$A$389,0.95,1,1) -> 467.22351
A395: 45745 | C395: =_xlfn.FORECAST.ETS(A395,$B$2:$B$389,$A$2:$A$389,1,1) -> 137.73775 | D395: =C395-_xlfn.FORECAST.ETS.CONFINT(A395,$B$2:$B$389,$A$2:$A$389,0.95,1,1) -> -200.82073 | E395: =C395+_xlfn.FORECAST.ETS.CONFINT(A395,$B$2:$B$389,$A$2:$A$389,0.95,1,1) -> 476.29624
A396: 45746 | C396: =_xlfn.FORECAST.ETS(A396,$B$2:$B$389,$A$2:$A$389,1,1) -> 118.84988 | D396: =C396-_xlfn.FORECAST.ETS.CONFINT(A396,$B$2:$B$389,$A$2:$A$389,0.95,1,1) -> -228.05928 | E396: =C396+_xlfn.FORECAST.ETS.CONFINT(A396,$B$2:$B$389,$A$2:$A$389,0.95,1,1) -> 465.75904
A397: 45747 | C397: =_xlfn.FORECAST.ETS(A397,$B$2:$B$389,$A$2:$A$389,1,1) -> 142.99679 | D397: =C397-_xlfn.FORECAST.ETS.CONFINT(A397,$B$2:$B$389,$A$2:$A$389,0.95,1,1) -> -212.12955 | E397: =C397+_xlfn.FORECAST.ETS.CONFINT(A397,$B$2:$B$389,$A$2:$A$389,0.95,1,1) -> 498.12312
A398: 45748 | C398: =_xlfn.FORECAST.ETS(A398,$B$2:$B$389,$A$2:$A$389,1,1) -> 80.650676 | D398: =C398-_xlfn.FORECAST.ETS.CONFINT(A398,$B$2:$B$389,$A$2:$A$389,0.95,1,1) -> -282.56864 | E398: =C398+_xlfn.FORECAST.ETS.CONFINT(A398,$B$2:$B$389,$A$2:$A$389,0.95,1,1) -> 443.86999
A399: 45749 | C399: =_xlfn.FORECAST.ETS(A399,$B$2:$B$389,$A$2:$A$389,1,1) -> 204.50058 | D399: =C399-_xlfn.FORECAST.ETS.CONFINT(A399,$B$2:$B$389,$A$2:$A$389,0.95,1,1) -> -166.69586 | E399: =C399+_xlfn.FORECAST.ETS.CONFINT(A399,$B$2:$B$389,$A$2:$A$389,0.95,1,1) -> 575.69703
A400: 45750 | C400: =_xlfn.FORECAST.ETS(A400,$B$2:$B$389,$A$2:$A$389,1,1) -> 287.32668 | D400: =C400-_xlfn.FORECAST.ETS.CONFINT(A400,$B$2:$B$389,$A$2:$A$389,0.95,1,1) -> -91.738599 | E400: =C400+_xlfn.FORECAST.ETS.CONFINT(A400,$B$2:$B$389,$A$2:$A$389,0.95,1,1) -> 666.39196
A401: 45751 | C401: =_xlfn.FORECAST.ETS(A401,$B$2:$B$389,$A$2:$A$389,1,1) -> 256.61919 | D401: =C401-_xlfn.FORECAST.ETS.CONFINT(A401,$B$2:$B$389,$A$2:$A$389,0.95,1,1) -> -130.21345 | E401: =C401+_xlfn.FORECAST.ETS.CONFINT(A401,$B$2:$B$389,$A$2:$A$389,0.95,1,1) -> 643.45184
... A647: 45997 | C647: =_xlfn.FORECAST.ETS(A647,$B$2:$B$389,$A$2:$A$389,1,1) -> 309.02124 | D647: =C647-_xlfn.FORECAST.ETS.CONFINT(A647,$B$2:$B$389,$A$2:$A$389,0.95,1,1) -> -1547.6783 | E647: =C647+_xlfn.FORECAST.ETS.CONFINT(A647,$B$2:$B$389,$A$2:$A$389,0.95,1,1) -> 2165.7207

Sheet Revenue Trend
A3: Row Labels | B3: Sum of money
A4: 2024
A5: March | B5: 5905.2
A6: April | B6: 5719.56
A7: May | B7: 8164.42
A8: June | B8: 7617.76
A9: July | B9: 6915.94
A10: August | B10: 7613.84
A11: September | B11: 9988.64
A12: October | B12: 13891.16
A13: November | B13: 8590.54
A14: December | B14: 8237.74
A15: 2025
A16: January | B16: 6398.86
A17: February | B17: 13215.48
A18: March | B18: 9986.44
A19: Grand Total | B19: 112245.58

Sheet SALES BY HOUR
A3: Row Labels | B3: Count of Index
A4: 10 | B4: 328
A5: 11 | B5: 283
A6: 16 | B6: 278
A7: 9 | B7: 242
A8: 12 | B8: 241
A9: 17 | B9: 237
A10: 15 | B10: 236
A11: 8 | B11: 235
A12: 19 | B12: 229
A13: 13 | B13: 225
A14: 14 | B14: 225
A15: 18 | B15: 218
... A20: 6 | B20: 5
A21: Grand Total | B21: 3547

Sheet Payment Types
A3: Row Labels | B3: Count of cash_type
A4: card | B4: 3547
A5: Grand Total | B5: 3547

Sheet Price Analysis
A3: Row Labels | B3: Start Date | C3: End Date | D3: Count of Index | E3: Sum of money | F3: Number of Days | G3: Average per day
A4: Americano | B4: 45352 | C4: 45739 | D4: 564 | E4: 14650.26
A5: 23.02 | B5: 45481 | C5: 45562 | D5: 98 | E5: 2255.96 | F5: =C5-B5 -> 81 | G5: =D5/F5 -> 1.2098765
A6: 25.96 | B6: 45564 | C6: 45739 | D6: 341 | E6: 8852.36 | F6: =C6-B6 -> 175 | G6: =D6/F6 -> 1.9485714
A7: 27.92 | B7: 45403 | C7: 45478 | D7: 72 | E7: 2010.24 | F7: =C7-B7 -> 75 | G7: =D7/F7 -> 0.96
A8: 28.9 | B8: 45352 | C8: 45402 | D8: 53 | E8: 1531.7 | F8: =C8-B8 -> 50 | G8: =D8/F8 -> 1.06
A9: Americano with Milk | B9: 45352 | C9: 45738 | D9: 809 | E9: 24751.12
A10: 27.92 | B10: 45479 | C10: 45563 | D10: 222 | E10: 6198.24 | F10: =C10-B10 -> 84 | G10: =D10/F10 -> 2.6428571
A11: 30.86 | B11: 45563 | C11: 45738 | D11: 389 | E11: 12004.54 | F11: =C11-B11 -> 175 | G11: =D11/F11 -> 2.2228571
A12: 32.82 | B12: 45402 | C12: 45478 | D12: 147 | E12: 4824.54 | F12: =C12-B12 -> 76 | G12: =D12/F12 -> 1.9342105
A13: 33.8 | B13: 45352 | C13: 45402 | D13: 51 | E13: 1723.8 | F13: =C13-B13 -> 50 | G13: =D13/F13 -> 1.02
A14: Cappuccino | B14: 45357 | C14: 45739 | D14: 486 | E14: 17439.14
A15: 32.82 | B15: 45480 | C15: 45562 | D15: 96 | E15: 3150.72 | F15: =C15-B15 -> 82 | G15: =D15/F15 -> 1.1707317
A16: 35.76 | B16: 45563 | C16: 45739 | D16: 235 | E16: 8403.6 | F16: =C16-B16 -> 176 | G16: =D16/F16 -> 1.3352273
A17: 37.72 | B17: 45402 | C17: 45478 | D17: 116 | E17: 4375.52 | F17: =C17-B17 -> 76 | G17: =D17/F17 -> 1.5263158
A18: 38.7 | B18: 45357 | C18: 45402 | D18: 39 | E18: 1509.3 | F18: =C18-B18 -> 45 | G18: =D18/F18 -> 0.86666667
A19: Cocoa | B19: 45352 | C19: 45739 | D19: 239 | E19: 8521.16
A20: 32.82 | B20: 45480 | C20: 45557 | D20: 27 | E20: 886.14 | F20: =C20-B20 -> 77 | G20: =D20/F20 -> 0.35064935
A21: 35.76 | B21: 45563 | C21: 45739 | D21: 189 | E21: 6758.64 | F21: =C21-B21 -> 176 | G21: =D21/F21 -> 1.0738636
A22: 37.72 | B22: 45408 | C22: 45478 | D22: 14 | E22: 528.08 | F22: =C22-B22 -> 70 | G22: =D22/F22 -> 0.2
A23: 38.7 | B23: 45352 | C23: 45401 | D23: 9 | E23: 348.3 | F23: =C23-B23 -> 49 | G23: =D23/F23 -> 0.18367347
A24: Cortado | B24: 45354 | C24: 45736 | D24: 287 | E24: 7384.86
A25: 23.02 | B25: 45485 | C25: 45562 | D25: 89 | E25: 2048.78 | F25: =C25-B25 -> 77 | G25: =D25/F25 -> 1.1558442
A26: 25.96 | B26: 45563 | C26: 45736 | D26: 118 | E26: 3063.28 | F26: =C26-B26 -> 173 | G26: =D26/F26 -> 0.68208092
A27: 27.92 | B27: 45408 | C27: 45471 | D27: 40 | E27: 1116.8 | F27: =C27-B27 -> 63 | G27: =D27/F27 -> 0.63492063
A28: 28.9 | B28: 45354 | C28: 45400 | D28: 40 | E28: 1156 | F28: =C28-B28 -> 46 | G28: =D28/F28 -> 0.86956522
A29: Espresso | B29: 45355 | C29: 45738 | D29: 129 | E29: 2690.28
A30: 18.12 | B30: 45491 | C30: 45561 | D30: 36 | E30: 652.32 | F30: =C30-B30 -> 70 | G30: =D30/F30 -> 0.51428571
A31: 21.06 | B31: 45571 | C31: 45738 | D31: 59 | E31: 1242.54 | F31: =C31-B31 -> 167 | G31: =D31/F31 -> 0.35329341
A32: 23.02 | B32: 45427 | C32: 45478 | D32: 21 | E32: 483.42 | F32: =C32-B32 -> 51 | G32: =D32/F32 -> 0.41176471
A33: 24 | B33: 45355 | C33: 45399 | D33: 13 | E33: 312 | F33: =C33-B33 -> 44 | G33: =D33/F33 -> 0.29545455
A34: Hot Chocolate | B34: 45352 | C34: 45738 | D34: 276 | E34: 9933.46
A35: 32.82 | B35: 45480 | C35: 45559 | D35: 26 | E35: 853.32 | F35: =C35-B35 -> 79 | G35: =D35/F35 -> 0.32911392
A36: 35.76 | B36: 45563 | C36: 45738 | D36: 193 | E36: 6901.68 | F36: =C36-B36 -> 175 | G36: =D36/F36 -> 1.1028571
A37: 37.72 | B37: 45408 | C37: 45473 | D37: 28 | E37: 1056.16 | F37: =C37-B37 -> 65 | G37: =D37/F37 -> 0.43076923
A38: 38.7 | B38: 45352 | C38: 45402 | D38: 29 | E38: 1122.3 | F38: =C38-B38 -> 50 | G38: =D38/F38 -> 0.58
A39: Latte | B39: 45352 | C39: 45739 | D39: 757 | E39: 26875.3
A40: 32.82 | B40: 45479 | C40: 45562 | D40: 194 | E40: 6367.08 | F40: =C40-B40 -> 83 | G40: =D40/F40 -> 2.3373494
A41: 35.76 | B41: 45563 | C41: 45739 | D41: 397 | E41: 14196.72 | F41: =C41-B41 -> 176 | G41: =D41/F41 -> 2.2556818
A42: 37.72 | B42: 45402 | C42: 45479 | D42: 115 | E42: 4337.8 | F42: =C42-B42 -> 77 | G42: =D42/F42 -> 1.4935065
...

Sheet Conclusions
A1: 0. Data Quality and Analysis Limitations
A2: The available dataset is incomplete and contains significant gaps, which limits the ability to perform a full, reliable business analysis. Nevertheless, the data is sufficient to identify key operational issues and provide practical recommendations that can support future growth.
A5: 1. Analysis of Traffic Patterns and Sales Volume
A6: The heatmap indicates that the peak activity occurs around 10 a.m. However, even during the busiest periods the overall sales volume remains extremely low. Total sales of 3547 units over more than 12 months translate to an average of fewer than 10 coffees sold per day. Such a sales level is far too low for the operation to be profitable in any form. Key conclusions: 1. Demand in the current location or under the current operating model is close to zero. 2. Even with maximum operational efficiency, this sales volume makes profitability unattainable - traffic must be increased, not only operating hours or pricing adjusted.
A15: 2. Payment Structure and Operational Consequences
A16: All transactions were processed exclusively via card payments. This may indicate: 1. lack of support for cash payments, 2. an error in the recording system, 3. intentional limitation of payment methods. If only card payments are accepted, this negatively affects the range of potential customers - particularly older individuals, some local customers, and those preferring small cash transactions.
A24: 3. Analysis of Revenue Trends and Pricing Policy
A25: The Revenue Trend suggests that the business operates in a highly unstable manner, with fluctuations not tied to seasonality or business growth. There is no indication of a positive trend. Analysis of the Price Analysis notebook reveals additional issues: 1. Pricing changes are inconsistent and not aligned with market data. 2. The pricing structure is inadequate for product categories - for example, espresso, which typically serves as an affordable entry-level item, is priced far above market norms, which is reflected in its extremely low sales. 3. The menu shows no seasonal adaptability (e.g. differences between winter and summer offerings). Recommendations: 1. Develop a complete and coherent price list based on local benchmarks. 2. Introduce seasonal menu variations and promotional “traffic boosters” (espresso, americano, small takeaway coffee). 3. Conduct a price elasticity analysis - current pricing may be suppressing demand instead of supporting margins.
A36: 4. Evaluation of Opening Hours and Operational Setup
A37: Heatmap data indicates that the current opening hours are suboptimal: 1. Early opening (e.g. 6 a.m.) generates no traffic. 2. The highest activity occurs later in the morning (around 10 a.m.). 3. Closing at 10 p.m. on weekdays is unjustified, as there is no traffic during those hours. 4. Fridays and Saturdays typically provide higher potential for evening traffic, yet the business does not take advantage of this. Recommendations: 1. Shift the café’s opening time to 7–8 a.m. 2. Introduce short morning promotions on weekdays (e.g. -10% for takeaway coffee). 3. Reduce weekday operating hours (e.g. closing between 7-8 p.m.). 4. Extend operating hours on weekends (Fridays and Saturdays) into late evening, if the location has evening potential.
A50: 5. Analysis of Forecast Reliability
A51: Historical data is highly unstable and shows no developmental direction. The forecasting model maintains values close to historical levels, while the confidence intervals expand rapidly, which implies: 1. a very high level of noise, 2. a lack of clear dependencies in the data, 3. low predictive capability for future performance. In practice, this means that without operational and marketing improvements, future sales are expected to remain close to zero.

Sheet Data Validation
A1: Index | B1: hour_of_day | C1: cash_type | D1: money | E1: coffee_name | F1: Time_of_Day | G1: Weekday | H1: Month_name | I1: Date | J1: PricePeriodID
A2: =_xlfn.XLOOKUP(E2,'Data Validation'!$M$3:$M$10,'Data Validation'!$N$3:$N$10) -> 1 | B2: 13 | C2: card | D2: 28.9 | E2: Americano | F2: Afternoon | G2: Friday | H2: March | I2: 45352 | J2: =1 -> 1
A3: =_xlfn.XLOOKUP(E3,'Data Validation'!$M$3:$M$10,'Data Validation'!$N$3:$N$10) -> 1 | B3: 10 | C3: card | D3: 28.9 | E3: Americano | F3: Morning | G3: Saturday | H3: March | I3: 45353 | J3: =IF(OR(E3<>E2,D3<>D2),J2+1,J2) -> 1 | M3: Americano | N3: 1
A4: =_xlfn.XLOOKUP(E4,'Data Validation'!$M$3:$M$10,'Data Validation'!$N$3:$N$10) -> 1 | B4: 14 | C4: card | D4: 28.9 | E4: Americano | F4: Afternoon | G4: Saturday | H4: March | I4: 45353 | J4: =IF(OR(E4<>E3,D4<>D3),J3+1,J3) -> 1 | M4: Americano with Milk | N4: 2
A5: =_xlfn.XLOOKUP(E5,'Data Validation'!$M$3:$M$10,'Data Validation'!$N$3:$N$10) -> 1 | B5: 17 | C5: card | D5: 28.9 | E5: Americano | F5: Night | G5: Saturday | H5: March | I5: 45353 | J5: =IF(OR(E5<>E4,D5<>D4),J4+1,J4) -> 1 | M5: Cappuccino | N5: 3
A6: =_xlfn.XLOOKUP(E6,'Data Validation'!$M$3:$M$10,'Data Validation'!$N$3:$N$10) -> 1 | B6: 12 | C6: card | D6: 28.9 | E6: Americano | F6: Afternoon | G6: Sunday | H6: March | I6: 45354 | J6: =IF(OR(E6<>E5,D6<>D5),J5+1,J5) -> 1 | M6: Cocoa | N6: 4
A7: =_xlfn.XLOOKUP(E7,'Data Validation'!$M$3:$M$10,'Data Validation'!$N$3:$N$10) -> 1 | B7: 13 | C7: card | D7: 28.9 | E7: Americano | F7: Afternoon | G7: Wednesday | H7: March | I7: 45357 | J7: =IF(OR(E7<>E6,D7<>D6),J6+1,J6) -> 1 | M7: Cortado | N7: 5
A8: =_xlfn.XLOOKUP(E8,'Data Validation'!$M$3:$M$10,'Data Validation'!$N$3:$N$10) -> 1 | B8: 15 | C8: card | D8: 28.9 | E8: Americano | F8: Afternoon | G8: Thursday | H8: March | I8: 45358 | J8: =IF(OR(E8<>E7,D8<>D7),J7+1,J7) -> 1 | M8: Espresso | N8: 6
A9: =_xlfn.XLOOKUP(E9,'Data Validation'!$M$3:$M$10,'Data Validation'!$N$3:$N$10) -> 1 | B9: 13 | C9: card | D9: 28.9 | E9: Americano | F9: Afternoon | G9: Friday | H9: March | I9: 45359 | J9: =IF(OR(E9<>E8,D9<>D8),J8+1,J8) -> 1 | M9: Hot Chocolate | N9: 7
A10: =_xlfn.XLOOKUP(E10,'Data Validation'!$M$3:$M$10,'Data Validation'!$N$3:$N$10) -> 1 | B10: 14 | C10: card | D10: 28.9 | E10: Americano | F10: Afternoon | G10: Friday | H10: March | I10: 45359 | J10: =IF(OR(E10<>E9,D10<>D9),J9+1,J9) -> 1 | M10: Latte | N10: 8
A11: =_xlfn.XLOOKUP(E11,'Data Validation'!$M$3:$M$10,'Data Validation'!$N$3:$N$10) -> 1 | B11: 14 | C11: card | D11: 28.9 | E11: Americano | F11: Afternoon | G11: Friday | H11: March | I11: 45359 | J11: =IF(OR(E11<>E10,D11<>D10),J10+1,J10) -> 1
A12: =_xlfn.XLOOKUP(E12,'Data Validation'!$M$3:$M$10,'Data Validation'!$N$3:$N$10) -> 1 | B12: 12 | C12: card | D12: 28.9 | E12: Americano | F12: Afternoon | G12: Saturday | H12: March | I12: 45360 | J12: =IF(OR(E12<>E11,D12<>D11),J11+1,J11) -> 1
A13: =_xlfn.XLOOKUP(E13,'Data Validation'!$M$3:$M$10,'Data Validation'!$N$3:$N$10) -> 1 | B13: 12 | C13: card | D13: 28.9 | E13: Americano | F13: Afternoon | G13: Saturday | H13: March | I13: 45360 | J13: =IF(OR(E13<>E12,D13<>D12),J12+1,J12) -> 1
A14: =_xlfn.XLOOKUP(E14,'Data Validation'!$M$3:$M$10,'Data Validation'!$N$3:$N$10) -> 1 | B14: 12 | C14: card | D14: 28.9 | E14: Americano | F14: Afternoon | G14: Saturday | H14: March | I14: 45360 | J14: =IF(OR(E14<>E13,D14<>D13),J13+1,J13) -> 1
A15: =_xlfn.XLOOKUP(E15,'Data Validation'!$M$3:$M$10,'Data Validation'!$N$3:$N$10) -> 1 | B15: 16 | C15: card | D15: 28.9 | E15: Americano | F15: Afternoon | G15: Monday | H15: March | I15: 45362 | J15: =IF(OR(E15<>E14,D15<>D14),J14+1,J14) -> 1
A16: =_xlfn.XLOOKUP(E16,'Data Validation'!$M$3:$M$10,'Data Validation'!$N$3:$N$10) -> 1 | B16: 10 | C16: card | D16: 28.9 | E16: Americano | F16: Morning | G16: Tuesday | H16: March | I16: 45363 | J16: =IF(OR(E16<>E15,D16<>D15),J15+1,J15) -> 1
A17: =_xlfn.XLOOKUP(E17,'Data Validation'!$M$3:$M$10,'Data Validation'!$N$3:$N$10) -> 1 | B17: 12 | C17: card | D17: 28.9 | E17: Americano | F17: Afternoon | G17: Tuesday | H17: March | I17: 45363 | J17: =IF(OR(E17<>E16,D17<>D16),J16+1,J16) -> 1
A18: =_xlfn.XLOOKUP(E18,'Data Validation'!$M$3:$M$10,'Data Validation'!$N$3:$N$10) -> 1 | B18: 16 | C18: card | D18: 28.9 | E18: Americano | F18: Afternoon | G18: Tuesday | H18: March | I18: 45363 | J18: =IF(OR(E18<>E17,D18<>D17),J17+1,J17) -> 1
A19: =_xlfn.XLOOKUP(E19,'Data Validation'!$M$3:$M$10,'Data Validation'!$N$3:$N$10) -> 1 | B19: 11 | C19: card | D19: 28.9 | E19: Americano | F19: Morning | G19: Wednesday | H19: March | I19: 45364 | J19: =IF(OR(E19<>E18,D19<>D18),J18+1,J18) -> 1
A20: =_xlfn.XLOOKUP(E20,'Data Validation'!$M$3:$M$10,'Data Validation'!$N$3:$N$10) -> 1 | B20: 12 | C20: card | D20: 28.9 | E20: Americano | F20: Afternoon | G20: Wednesday | H20: March | I20: 45364 | J20: =IF(OR(E20<>E19,D20<>D19),J19+1,J19) -> 1
A21: =_xlfn.XLOOKUP(E21,'Data Validation'!$M$3:$M$10,'Data Validation'!$N$3:$N$10) -> 1 | B21: 12 | C21: card | D21: 28.9 | E21: Americano | F21: Afternoon | G21: Wednesday | H21: March | I21: 45364 | J21: =IF(OR(E21<>E20,D21<>D20),J20+1,J20) -> 1
A22: =_xlfn.XLOOKUP(E22,'Data Validation'!$M$3:$M$10,'Data Validation'!$N$3:$N$10) -> 1 | B22: 13 | C22: card | D22: 28.9 | E22: Americano | F22: Afternoon | G22: Thursday | H22: March | I22: 45365 | J22: =IF(OR(E22<>E21,D22<>D21),J21+1,J21) -> 1
... A3548: =_xlfn.XLOOKUP(E3548,'Data Validation'!$M$3:$M$10,'Data Validation'!$N$3:$N$10) -> 8 | B3548: 18 | C3548: card | D3548: 35.76 | E3548: Latte | F3548: Night | G3548: Sunday | H3548: March | I3548: 45739 | J3548: =IF(OR(E3548<>E3547,D3548<>D3547),J3547+1,J3547) -> 32

Sheet Sort Data 
A1: hour_of_day | B1: cash_type | C1: money | D1: coffee_name | E1: Time_of_Day | F1: Weekday | G1: Month_name | H1: Weekdaysort | I1: Monthsort
A2: 6 | B2: card | C2: 38.7 | D2: Americano | E2: Morning | F2: Monday | G2: January | H2: 1 | I2: 1
A3: 7 | C3: 28.9 | D3: Americano with Milk | E3: Afternoon | F3: Tuesday | G3: February | H3: 2 | I3: 2
A4: 8 | C4: 33.8 | D4: Cappuccino | E4: Night | F4: Wednesday | G4: March | H4: 3 | I4: 3
A5: 9 | C5: 24 | D5: Cocoa | F5: Thursday | G5: April | H5: 4 | I5: 4
A6: 10 | C6: 32.82 | D6: Cortado | F6: Friday | G6: May | H6: 5 | I6: 5
A7: 11 | C7: 37.72 | D7: Espresso | F7: Saturday | G7: June | H7: 6 | I7: 6
A8: 12 | C8: 27.92 | D8: Hot Chocolate | F8: Sunday | G8: July | H8: 7 | I8: 7
A9: 13 | C9: 23.02 | D9: Latte | G9: August | I9: 8
A10: 14 | C10: 18.12 | G10: September | I10: 9
A11: 15 | C11: 35.76 | G11: October | I11: 10
A12: 16 | C12: 30.86 | G12: November | I12: 11
A13: 17 | C13: 25.96 | G13: December | I13: 12
A14: 18 | C14: 21.06
A15: 19
A16: 20
A17: 21
A18: 22

Sheet Sales Data
A1: hour_of_day | B1: cash_type | C1: money | D1: coffee_name | E1: Time_of_Day | F1: Weekday | G1: Month_name | H1: Weekdaysort | I1: Monthsort | J1: Date | K1: Time
A2: 10 | B2: card | C2: 38.7 | D2: Latte | E2: Morning | F2: Fri | G2: Mar | H2: 5 | I2: 3 | J2: 45352 | K2: 0.42766204
A3: 12 | B3: card | C3: 38.7 | D3: Hot Chocolate | E3: Afternoon | F3: Fri | G3: Mar | H3: 5 | I3: 3 | J3: 45352 | K3: 0.51344907
A4: 12 | B4: card | C4: 38.7 | D4: Hot Chocolate | E4: Afternoon | F4: Fri | G4: Mar | H4: 5 | I4: 3 | J4: 45352 | K4: 0.51409722
A5: 13 | B5: card | C5: 28.9 | D5: Americano | E5: Afternoon | F5: Fri | G5: Mar | H5: 5 | I5: 3 | J5: 45352 | K5: 0.57399306
A6: 13 | B6: card | C6: 38.7 | D6: Latte | E6: Afternoon | F6: Fri | G6: Mar | H6: 5 | I6: 3 | J6: 45352 | K6: 0.57516204
A7: 15 | B7: card | C7: 33.8 | D7: Americano with Milk | E7: Afternoon | F7: Fri | G7: Mar | H7: 5 | I7: 3 | J7: 45352 | K7: 0.65262731
A8: 16 | B8: card | C8: 38.7 | D8: Hot Chocolate | E8: Afternoon | F8: Fri | G8: Mar | H8: 5 | I8: 3 | J8: 45352 | K8: 0.67988426
A9: 18 | B9: card | C9: 33.8 | D9: Americano with Milk | E9: Night | F9: Fri | G9: Mar | H9: 5 | I9: 3 | J9: 45352 | K9: 0.77711806
A10: 19 | B10: card | C10: 38.7 | D10: Cocoa | E10: Night | F10: Fri | G10: Mar | H10: 5 | I10: 3 | J10: 45352 | K10: 0.80695602
A11: 19 | B11: card | C11: 33.8 | D11: Americano with Milk | E11: Night | F11: Fri | G11: Mar | H11: 5 | I11: 3 | J11: 45352 | K11: 0.8078125
A12: 19 | B12: card | C12: 33.8 | D12: Americano with Milk | E12: Night | F12: Fri | G12: Mar | H12: 5 | I12: 3 | J12: 45352 | K12: 0.81200231
A13: 10 | B13: card | C13: 28.9 | D13: Americano | E13: Morning | F13: Sat | G13: Mar | H13: 6 | I13: 3 | J13: 45353 | K13: 0.43201389
... A3548: 18 | B3548: card | C3548: 35.76 | D3548: Latte | E3548: Night | F3548: Sun | G3548: Mar | H3548: 7 | I3548: 3 | J3548: 45739 | K3548: 0.7580787
